Workbook

Sheet Summary
A1: What It Costs to Run
A2: One deployment: five always-running job workers, a web/API tier, one set of storage. Infrastructure only - the model API is costed in cloud-architecture.xlsx.
B4: Typical $ / month | C4: Peak $ / month | D4: Typical $ / year
A5: A. Fargate, all on-demand | B5: ='Compute - EC2 vs Fargate'!C11 | C5: ='Compute - EC2 vs Fargate'!D11 | D5: =B5*12 | E5: Simplest. No servers to run.
A6: B. Fargate, workers on Spot | B6: ='Compute - EC2 vs Fargate'!C15 | C6: ='Compute - EC2 vs Fargate'!D15 | D6: =B6*12 | E6: Workers on spare capacity at about 70% off.
A7: C. ECS on EC2 | B7: ='Compute - EC2 vs Fargate'!C20 | C7: ='Compute - EC2 vs Fargate'!D20 | D7: =B7*12 | E7: Whole machines. Cheaper only when kept busy.
A9: Storage | B9: =Storage!C7 | C9: =Storage!C7 | D9: =B9*12 | E9: Document store at today's 500 MB, plus the file store.
A10: Other cloud infrastructure | B10: ='Other cloud infra'!C11 | C10: ='Other cloud infra'!C11 | D10: =B10*12 | E10: Load balancer, egress, logs, backup, registry.
A12: TOTAL with option A (Fargate on-demand) | B12: =B5+B9+B10 | C12: =C5+C9+C10 | D12: =B12*12
A13: TOTAL with option B (Fargate + Spot workers) | B13: =B6+B9+B10 | C13: =C6+C9+C10 | D13: =B13*12 | E13: RECOMMENDED
A14: TOTAL with option C (ECS on EC2) | B14: =B7+B9+B10 | C14: =C7+C9+C10 | D14: =B14*12
A16: RECOMMENDATION
A17: Fargate, with the five job workers on Spot capacity.
A18: The five always-on workers are the biggest compute line, and Spot cuts them by about 70% - a bigger saving than any
A19: choice between EC2 and Fargate. An interrupted job goes back on the queue and another worker picks it up, which the
A20: queue already does anyway, so nothing has to be designed for it.
A21: The web containers stay on-demand, because an interrupted web request is visible to somebody.
A22: EC2 loses because the platform needs 6 cores and the smallest build that survives losing a node buys 12. Revisit it
A23: only when the machines would be kept genuinely busy - that is a utilisation question, not a headcount one.
A25: Prices are us-east-1 list prices, copied by hand, and will go stale. Hosting in the UAE adds roughly 15-20%. Check before quoting.

Sheet Compute - EC2 vs Fargate
A1: Compute: EC2 vs Fargate
A2: The same workload priced three ways. Five job workers run at all times either way; only the web tier changes between typical and peak.
A4: WHAT HAS TO RUN | C4: Typical | D4: Peak
A5: Job workers (always on) | B5: The five instances - unchanged in both columns | C5: =Assumptions!$B$10 | D5: =Assumptions!$B$10 | E5: containers
A6: Web/API containers | B6: Scales with how many people are on the screens | C6: =Assumptions!$B$15 | D6: =Assumptions!$B$16 | E6: containers
A7: Processor demand | C7: =(Assumptions!$B$10*Assumptions!$B$11+Assumptions!$B$15*Assumptions!$B$17) | D7: =(Assumptions!$B$10*Assumptions!$B$11+Assumptions!$B$16*Assumptions!$B$19) | E7: cores
A8: Memory demand | C8: =(Assumptions!$B$10*Assumptions!$B$12+Assumptions!$B$15*Assumptions!$B$18) | D8: =(Assumptions!$B$10*Assumptions!$B$12+Assumptions!$B$16*Assumptions!$B$20) | E8: GB
A10: OPTION | B10: How it is worked out | C10: Typical $ / month | D10: Peak $ / month | E10: Note
A11: A. Fargate, all on-demand | C11: =C12+C13 | D11: =D12+D13 | E11: Pay per container-second. No servers to run.
A12: Five job workers | B12: =Assumptions!$B$10&" containers x "&Assumptions!$B$11&" core / "&Assumptions!$B$12&" GB x "&Assumptions!$B$6&" hours" | C12: =(Assumptions!$B$10*(Assumptions!$B$11*Assumptions!$B$28+Assumptions!$B$12*Assumptions!$B$29)*Assumptions!$B$6) | D12: =(Assumptions!$B$10*(Assumptions!$B$11*Assumptions!$B$28+Assumptions!$B$12*Assumptions!$B$29)*Assumptions!$B$6) | E12: Identical in both columns - they are always on.
A13: Web/API containers | B13: =Assumptions!$B$15&" typical, "&Assumptions!$B$16&" at peak" | C13: =(Assumptions!$B$15*(Assumptions!$B$17*Assumptions!$B$28+Assumptions!$B$18*Assumptions!$B$29)*Assumptions!$B$6) | D13: =(Assumptions!$B$16*(Assumptions!$B$19*Assumptions!$B$28+Assumptions!$B$20*Assumptions!$B$29)*Assumptions!$B$6) | E13: The only compute line that moves.
A15: B. Fargate, workers on Spot | C15: =C16+C17 | D15: =D16+D17 | E15: Workers run on spare capacity at about 70% off.
A16: Five job workers (Spot) | B16: An interrupted job returns to the queue and another worker takes it | C16: =(Assumptions!$B$10*(Assumptions!$B$11*Assumptions!$B$30+Assumptions!$B$12*Assumptions!$B$31)*Assumptions!$B$6) | D16: =(Assumptions!$B$10*(Assumptions!$B$11*Assumptions!$B$30+Assumptions!$B$12*Assumptions!$B$31)*Assumptions!$B$6) | E16: The queue already redelivers, so this costs nothing in design.
A17: Web/API containers | B17: On-demand - an interrupted web request is visible to somebody | C17: =C13 | D17: =D13
A18: Saving against option A | C18: =C15-C11 | D18: =D15-D11 | E18: Negative is cheaper.
A20: C. ECS on EC2 | C20: =C21+C22 | D20: =D21+D22 | E20: You rent whole machines and pack containers onto them.
A21: m7g.xlarge nodes | B21: =Assumptions!$B$37&" nodes x $"&Assumptions!$B$34&" per hour" | C21: =Assumptions!$B$37*Assumptions!$B$34*Assumptions!$B$6 | D21: =Assumptions!$B$38*Assumptions!$B$34*Assumptions!$B$6 | E21: Charged whole, all month, whether containers use them or not.
A22: Disk for those nodes | B22: =Assumptions!$B$25&" GB per node" | C22: =Assumptions!$B$37*Assumptions!$B$25*Assumptions!$B$39 | D22: =Assumptions!$B$38*Assumptions!$B$25*Assumptions!$B$39 | E22: Fargate needs no equivalent.
A23: Processor capacity bought | C23: =Assumptions!$B$37*Assumptions!$B$35 | D23: =Assumptions!$B$38*Assumptions!$B$35 | E23: cores
A24: Processor capacity actually needed | C24: =(Assumptions!$B$10*Assumptions!$B$11+Assumptions!$B$15*Assumptions!$B$17) | D24: =(Assumptions!$B$10*Assumptions!$B$11+Assumptions!$B$16*Assumptions!$B$19) | E24: cores
A25: Paid for and unused | C25: =C23/C24-1 | D25: =D23/D24-1 | E25: A node has to be spare, or losing one takes the platform down.
A26: Difference against option A | C26: =C20-C11 | D26: =D20-D11 | E26: Negative is cheaper.
A28: VERDICT
A29: Cheapest in a typical month | C29: =MIN(C11,C15,C20) | E29: =IF(C15<=MIN(C11,C20),"Option B - Fargate with Spot workers",IF(C20<C11,"Option C - ECS on EC2","Option A - Fargate on-demand"))
A30: Cheapest at peak | C30: =MIN(D11,D15,D20) | E30: =IF(D15<=MIN(D11,D20),"Option B - Fargate with Spot workers",IF(D20<D11,"Option C - ECS on EC2","Option A - Fargate on-demand"))
A32: Why EC2 does not win: the platform needs 6 cores, and the smallest EC2 build that survives losing a node buys 12.
A33: Fargate bills per container, so it buys exactly what runs. EC2 only pulls ahead once the machines are kept genuinely busy.
A34: EC2 also brings work Fargate does not: patching the operating system, draining nodes on deploy, and scaling machines as well as containers.
A35: Spot is the real saving here. Five always-on workers are the largest compute line, and they are exactly the workload Spot suits.

Sheet Storage
A1: Storage
A2: One set for the whole platform. The document store holds the RFQ paperwork; the file store holds the system's own records.
C4: $ / month
A5: Document store - the RFQ paperwork | B5: =Assumptions!$B$23&" GB x $"&Assumptions!$B$42&" per GB" | C5: =Assumptions!$B$23*Assumptions!$B$42 | E5: S3 Standard
A6: System file store | B6: =Assumptions!$B$24&" GB x $"&Assumptions!$B$43&" per GB" | C6: =Assumptions!$B$24*Assumptions!$B$43 | E6: EFS - accounts, workflow, bidder registry
A7: Storage total | C7: =C5+C6
A9: A NOTE ON 500 MB
A10: 500 MB is roughly 11 tenders - one tender's documents in the reference corpus measured 44 MB.
A11: At 500 MB of paperwork arriving each week, the store passes 500 MB in week one and reaches about 26 GB after a year.
A12: The table below is the figure to budget against. Document storage is not where the money goes - compute is.
A14: IF THE DOCUMENT STORE GROWS TO... | B14: $ / month | C14: Share of a typical month's bill
A15: 500 MB (today's figure) | B15: =0.5*Assumptions!$B$42 | C15: =0.5*Assumptions!$B$42/Summary!$B$13
A16: 5 GB | B16: =5*Assumptions!$B$42 | C16: =5*Assumptions!$B$42/Summary!$B$13
A17: 26 GB (one year at 500 MB/week) | B17: =26*Assumptions!$B$42 | C17: =26*Assumptions!$B$42/Summary!$B$13
A18: 100 GB | B18: =100*Assumptions!$B$42 | C18: =100*Assumptions!$B$42/Summary!$B$13
A19: 500 GB | B19: =500*Assumptions!$B$42 | C19: =500*Assumptions!$B$42/Summary!$B$13
A20: 1 TB | B20: =1024*Assumptions!$B$42 | C20: =1024*Assumptions!$B$42/Summary!$B$13
A21: 5 TB | B21: =5120*Assumptions!$B$42 | C21: =5120*Assumptions!$B$42/Summary!$B$13
A23: Even at 5 TB, document storage costs less per month than the load balancer.
A24: S3 charges only for what is stored, so there is no capacity to buy up front and nothing to resize later.

Sheet Other cloud infra
A1: Other Cloud Infrastructure
A2: Supporting services. One of each for the whole platform - none of it scales with users.
A4: Component | B4: What it does | C4: $ / month
A5: Load balancer | B5: The single public entry point; sends each visitor to a healthy web container | C5: =Assumptions!$B$46
A6: NAT Gateways x2 | B6: Lets containers reach the model provider while staying unreachable from the internet | C6: =Assumptions!$B$47
A7: VPC endpoints x8 | B7: Private routes for image pulls, logs and secrets - keeps that traffic off the NAT | C7: =Assumptions!$B$48
A8: Logs | B8: Application logs, access logs and job outcomes | C8: =Assumptions!$B$49
A9: Backup and snapshots | B9: Scheduled copies of the file store. There is no second copy anywhere | C9: =Assumptions!$B$50
A10: Registry, DNS, secrets, certificate, scheduler | B10: The plumbing - between them about two dollars a month | C10: =Assumptions!$B$51
A11: Other infrastructure total | C11: =SUM(C5:C10)

Sheet Assumptions
A1: Assumptions & Rates
A2: Every figure on the other tabs comes from here. Blue = change it.
A4: Item | B4: Value | C4: Unit | D4: Basis
A5: SCALE - one platform, one organisation
A6: Hours per month | B6: 730 | C6: hours | D6: 365 x 24 / 12
A7: People who can sign in | B7: 50 | C7: users | D7: Agreed
A9: BACKEND JOB WORKERS - the five always-running instances
A10: Job workers running at all times | B10: 5 | C10: containers | D10: The requirement: five, always up
A11: Processor cores per worker | B11: 1 | C11: vCPU | D11: Fixed at container start - cannot be resized while running
A12: Memory per worker | B12: 4 | C12: GB | D12: Sized for the largest job: a 220k-character proposal
A14: WEB / API TIER
A15: Web/API containers - typical | B15: 2 | C15: containers | D15: Two zones - the availability floor
A16: Web/API containers - peak | B16: 4 | C16: containers | D16: ESTIMATED - scales on request load
A17: Processor cores each - typical | B17: 0.5 | C17: vCPU | D17: Mostly waiting on I/O
A18: Memory each - typical | B18: 1 | C18: GB | D18: FastAPI plus the compiled front end
A19: Processor cores each - peak | B19: 1 | C19: vCPU | D19: ESTIMATED
A20: Memory each - peak | B20: 2 | C20: GB | D20: Upload buffering
A22: STORAGE - one set for the whole platform
A23: Document store | B23: 0.5 | C23: GB | D23: YOUR FIGURE - 500 MB of RFQ documents
A24: System file store | B24: 50 | C24: GB | D24: ESTIMATED - accounts, workflow, bidder registry
A25: Disk per EC2 node | B25: 100 | C25: GB | D25: ESTIMATED - EC2 option only
A27: FARGATE PRICES - us-east-1 list
A28: Fargate - per core-hour | B28: 0.04048 | C28: $ | D28: AWS list price
A29: Fargate - per GB-hour | B29: 0.004445 | C29: $ | D29: AWS list price
A30: Fargate SPOT - per core-hour | B30: 0.012144 | C30: $ | D30: About 70% off on-demand
A31: Fargate SPOT - per GB-hour | B31: 0.0013335 | C31: $ | D31: About 70% off on-demand
A33: EC2 PRICES - us-east-1 list
A34: m7g.xlarge - per hour | B34: 0.1632 | C34: $ | D34: AWS list price, Graviton
A35: m7g.xlarge - cores | B35: 4 | C35: vCPU
A36: m7g.xlarge - memory | B36: 16 | C36: GB
A37: Nodes - typical | B37: 3 | C37: count | D37: 2 fits, but losing one would take the platform down
A38: Nodes - peak | B38: 4 | C38: count | D38: Covers peak demand and still survives losing a node
A39: EBS gp3 - per GB-month | B39: 0.08 | C39: $ | D39: AWS list price
A41: STORAGE PRICES
A42: S3 Standard - per GB-month | B42: 0.023 | C42: $ | D42: AWS list price
A43: EFS Standard - per GB-month | B43: 0.3 | C43: $ | D43: AWS list price
A45: OTHER CLOUD INFRASTRUCTURE
A46: Load balancer | B46: 46 | C46: $/month | D46: Fixed hourly charge plus capacity units
A47: NAT Gateways x2 | B47: 68 | C47: $/month | D47: Egress to the model provider
A48: VPC endpoints x8 | B48: 58 | C48: $/month | D48: Keeps AWS traffic off the NAT
...
